<?xml version="1.0" ?>
<!-- =================================================================================== -->
<!-- |    This document was autogenerated by xacro from ./src/robot_description/models/myCar/BMW.urdf.xacro | -->
<!-- |    EDITING THIS FILE BY HAND IS NOT RECOMMENDED                                 | -->
<!-- =================================================================================== -->
<robot name="BMW_Car">
  <material name="blue">
    <color rgba="0 0.2 0.9 1"/>
  </material>
  <material name="gray">
    <color rgba="0.1 0.1 0.1 1"/>
  </material>
  <material name="darkBlue">
    <color rgba="0 0 0.1 1"/>
  </material>
  <link name="dummy_link"/>
  <!-- Chassis -->
  <link name="chassis">
    <visual>
      <geometry>
        <box size="0.6 0.7 0.1"/>
      </geometry>
      <origin rpy="0 0 1.57" xyz="0 0 0"/>
      <material name="darkBlue"/>
    </visual>
    <collision>
      <geometry>
        <box size="0.6 0.7 0.1"/>
      </geometry>
      <origin rpy="0 0 1.57" xyz="0 0 0"/>
    </collision>
    <inertial>
      <origin rpy="0 0 1.57" xyz="0 0 0"/>
      <mass value="0.1"/>
      <inertia ixx="0.004166666666666666" ixy="0.0" ixz="0.0" iyy="0.0030833333333333333" iyz="0.0" izz="0.007083333333333332"/>
    </inertial>
  </link>
  <joint name="chassis_joint" type="fixed">
    <parent link="dummy_link"/>
    <child link="chassis"/>
    <origin xyz="0 0 0"/>
  </joint>
  <gazebo reference="chassis">
    <material>Gazebo/DarkMagentaTransparent</material>
  </gazebo>
  <!-- Front Left Wheel -->
  <link name="LB_wheel">
    <visual>
      <geometry>
        <cylinder length="0.07" radius="0.2"/>
      </geometry>
      <material name="gray"/>
    </visual>
    <collision>
      <geometry>
        <sphere radius="0.2"/>
      </geometry>
    </collision>
    <inertial>
      <origin rpy="0 0 0" xyz="0 0 0"/>
      <mass value="0.05"/>
      <inertia ixx="0.0005204166666666667" ixy="0.0" ixz="0.0" iyy="0.0005204166666666667" iyz="0.0" izz="0.0010000000000000002"/>
    </inertial>
  </link>
  <joint name="LB_wheel_joint" type="continuous">
    <parent link="chassis"/>
    <child link="LB_wheel"/>
    <origin rpy="0 1.57 -1.57" xyz="-0.333 0.333 0"/>
    <axis xyz="0 0 -1"/>
  </joint>
  <gazebo reference="LB_wheel">
    <material>Gazebo/Black</material>
    <mu1 value="0.2"/>
    <mu2 value="0.2"/>
  </gazebo>
  <!-- Back Left wheel -->
  <link name="RB_wheel">
    <visual>
      <geometry>
        <cylinder length="0.07" radius="0.2"/>
      </geometry>
      <material name="gray"/>
    </visual>
    <collision>
      <geometry>
        <sphere radius="0.2"/>
      </geometry>
    </collision>
    <inertial>
      <origin rpy="0 0 0" xyz="0 0 0"/>
      <mass value="0.05"/>
      <inertia ixx="0.0005204166666666667" ixy="0.0" ixz="0.0" iyy="0.0005204166666666667" iyz="0.0" izz="0.0010000000000000002"/>
    </inertial>
  </link>
  <joint name="RB_wheel_joint" type="continuous">
    <parent link="chassis"/>
    <child link="RB_wheel"/>
    <origin rpy="0 1.57 -1.57" xyz="-0.333 -0.333 0"/>
    <axis xyz="0 0 -1"/>
  </joint>
  <gazebo reference="RB_wheel">
    <material>Gazebo/Black</material>
    <mu1 value="0.2"/>
    <mu2 value="0.2"/>
  </gazebo>
  <!-- Front Right Wheel -->
  <link name="LF_wheel">
    <visual>
      <geometry>
        <cylinder length="0.07" radius="0.2"/>
      </geometry>
      <material name="gray"/>
    </visual>
    <collision>
      <geometry>
        <sphere radius="0.2"/>
      </geometry>
    </collision>
    <inertial>
      <origin rpy="0 0 0" xyz="0 0 0"/>
      <mass value="0.05"/>
      <inertia ixx="0.0005204166666666667" ixy="0.0" ixz="0.0" iyy="0.0005204166666666667" iyz="0.0" izz="0.0010000000000000002"/>
    </inertial>
  </link>
  <joint name="LF_wheel_joint" type="continuous">
    <parent link="chassis"/>
    <child link="LF_wheel"/>
    <origin rpy="0 1.57 -1.57" xyz="0.333 0.333 0"/>
    <axis xyz="0 0 -1"/>
  </joint>
  <gazebo reference="LF_wheel">
    <material>Gazebo/Black</material>
    <mu1 value="0.2"/>
    <mu2 value="0.2"/>
  </gazebo>
  <!-- Back Right Wheel -->
  <link name="RF_wheel">
    <visual>
      <geometry>
        <cylinder length="0.07" radius="0.2"/>
      </geometry>
      <material name="gray"/>
    </visual>
    <collision>
      <geometry>
        <sphere radius="0.2"/>
      </geometry>
    </collision>
    <inertial>
      <origin rpy="0 0 0" xyz="0 0 0"/>
      <mass value="0.05"/>
      <inertia ixx="0.0005204166666666667" ixy="0.0" ixz="0.0" iyy="0.0005204166666666667" iyz="0.0" izz="0.0010000000000000002"/>
    </inertial>
  </link>
  <joint name="RF_wheel_joint" type="continuous">
    <parent link="chassis"/>
    <child link="RF_wheel"/>
    <origin rpy="0 1.57 -1.57" xyz="0.333 -0.333 0"/>
    <axis xyz="0 0 -1"/>
  </joint>
  <gazebo reference="RF_wheel">
    <material>Gazebo/Black</material>
    <mu1 value="0.2"/>
    <mu2 value="0.2"/>
  </gazebo>
  <!-- Lidar -->
  <link name="lidar">
    <visual>
      <geometry>
        <cylinder length="0.25" radius="0.15"/>
      </geometry>
      <origin rpy="0 0 0" xyz="-0.16 0 0.1"/>
      <material name="blue"/>
    </visual>
    <collision>
      <geometry>
        <cylinder length="0.25" radius="0.15"/>
      </geometry>
      <origin rpy="0 0 0" xyz="-0.16 0 0.1"/>
    </collision>
    <inertial>
      <origin rpy="0 0 0" xyz="-0.16 0 0.1"/>
      <mass value="0.1"/>
      <inertia ixx="0.0010833333333333333" ixy="0.0" ixz="0.0" iyy="0.0010833333333333333" iyz="0.0" izz="0.001125"/>
    </inertial>
  </link>
  <joint name="lidar_joint" type="fixed">
    <parent link="chassis"/>
    <child link="lidar"/>
    <origin rpy="0 0 0" xyz="0 0 0"/>
  </joint>
  <gazebo reference="lidar">
    <material>Gazebo/Indigo</material>
  </gazebo>
  <!-- Camera-->
  <link name="camera">
    <visual>
      <geometry>
        <box size="0.15 0.15 0.08"/>
      </geometry>
      <origin rpy="0 0 0" xyz="0.2 0 0.05"/>
      <material name="blue"/>
    </visual>
    <collision>
      <geometry>
        <box size="0.15 0.15 0.08"/>
      </geometry>
      <origin rpy="0 0 0" xyz="0.2 0 0.05"/>
    </collision>
    <inertial>
      <origin rpy="0 0 0" xyz="0 0 0"/>
      <mass value="0.05"/>
      <inertia ixx="0.00012041666666666666" ixy="0.0" ixz="0.0" iyy="0.00012041666666666666" iyz="0.0" izz="0.0001875"/>
    </inertial>
  </link>
  <joint name="camera_joint" type="fixed">
    <parent link="chassis"/>
    <child link="camera"/>
    <origin rpy="0 0 0" xyz="0 0 0"/>
  </joint>
  <gazebo reference="camera">
    <material>Gazebo/Indigo</material>
  </gazebo>
  <gazebo>
    <plugin filename="libgazebo_ros_diff_drive.so" name="skid_steer_drive">
      <!-- Update rate -->
      <update_rate>500</update_rate>
      <!-- Number of wheel pairs -->
      <num_wheel_pairs>2</num_wheel_pairs>
      <!-- wheels0 -->
      <left_joint>LF_wheel_joint</left_joint>
      <right_joint>RF_wheel_joint</right_joint>
      <!-- wheels1-->
      <left_joint>LB_wheel_joint</left_joint>
      <right_joint>RB_wheel_joint</right_joint>
      <!-- kinematics -->
      <wheel_separation>0.6</wheel_separation>
      <wheel_separation>0.6</wheel_separation>
      <wheel_diameter>0.4</wheel_diameter>
      <wheel_diameter>0.4</wheel_diameter>
      <!-- limits -->
      <max_wheel_torque>200</max_wheel_torque>
      <max_wheel_acceleration>10.0</max_wheel_acceleration>
      <!-- output -->
      <odometry_frame>odom</odometry_frame>
      <robot_base_frame>dummy_link</robot_base_frame>
      <publish_odom>true</publish_odom>
      <publish_odom_tf>true</publish_odom_tf>
      <publish_wheel_tf>true</publish_wheel_tf>
    </plugin>
  </gazebo>
  <gazebo reference="lidar">
    <sensor name="lidar_sensor" type="ray">
      <pose>0 0 0 0 0 0</pose>
      <always_on>true</always_on>
      <visualize>true</visualize>
      <update_rate>10</update_rate>
      <ray>
        <scan>
          <horizontal>
            <samples>360</samples>
            <min_angle>0.0</min_angle>
            <max_angle>6.28</max_angle>
          </horizontal>
        </scan>
        <range>
          <min>1.0</min>
          <max>5.5</max>
        </range>
      </ray>
      <plugin filename="libgazebo_ros_ray_sensor.so" name="laser_controller">
        <ros>
          <!-- publish LaserScan message to the topic scan-->
          <argument>~/out:=scan</argument>
        </ros>
        <output_type>sensor_msgs/LaserScan</output_type>
        <frame_name>lidar</frame_name>
        <!-- lidar link name-->
      </plugin>
    </sensor>
  </gazebo>
  <gazebo reference="camera">
    <sensor name="camera1" type="camera">
      <update_rate>10.0</update_rate>
      <camera name="camera1">
        <pose>1 0 0 0 0 0</pose>
        <horizontal_fov>1.4</horizontal_fov>
        <image>
          <width>800</width>
          <height>800</height>
          <format>BGR8</format>
        </image>
        <clip>
          <near>0.02</near>
          <far>8.0</far>
        </clip>
      </camera>
      <plugin filename="libgazebo_ros_camera.so" name="camera_controller">
        <frameName>camera</frameName>
      </plugin>
    </sensor>
  </gazebo>
</robot>
