<?xml version="1.0" ?>
<!-- =================================================================================== -->
<!-- |    This document was autogenerated by xacro from ./src/robot_description/models/myCar/BMW.urdf.xacro | -->
<!-- |    EDITING THIS FILE BY HAND IS NOT RECOMMENDED                                 | -->
<!-- =================================================================================== -->
<robot name="BMW_Car">
  <material name="blue">
    <color rgba="0 0.2 0.9 1"/>
  </material>
  <material name="gray">
    <color rgba="0.1 0.1 0.1 1"/>
  </material>
  <material name="darkBlue">
    <color rgba="0 0 0.1 1"/>
  </material>
  <link name="dummy_link"/>
  <!-- Chassis -->
  <link name="chassis">
    <visual>
      <geometry>
        <box size="0.6 0.7 0.1"/>
      </geometry>
      <origin rpy="0 0 1.57" xyz="0 0 0"/>
      <material name="darkBlue"/>
    </visual>
    <collision>
      <geometry>
        <box size="0.6 0.7 0.1"/>
      </geometry>
      <origin rpy="0 0 1.57" xyz="0 0 0"/>
    </collision>
    <inertial>
      <origin rpy="0 0 1.57" xyz="0 0 0"/>
      <mass value="0.5"/>
      <inertia ixx="0.02083333333333333" ixy="0.0" ixz="0.0" iyy="0.015416666666666665" iyz="0.0" izz="0.03541666666666666"/>
    </inertial>
  </link>
  <joint name="chassis_joint" type="fixed">
    <parent link="dummy_link"/>
    <child link="chassis"/>
    <origin xyz="0 0 0"/>
  </joint>
  <gazebo reference="chassis">
    <material>Gazebo/DarkMagentaTransparent</material>
  </gazebo>
  <!-- Front Left Wheel -->
  <link name="LF_wheel">
    <visual>
      <geometry>
        <cylinder length="0.07" radius="0.2"/>
      </geometry>
      <material name="gray"/>
    </visual>
    <collision>
      <geometry>
        <cylinder length="0.07" radius="0.2"/>
      </geometry>
    </collision>
    <inertial>
      <origin rpy="0 0 0" xyz="0 0 0"/>
      <mass value="0.1"/>
      <inertia ixx="0.0010408333333333335" ixy="0.0" ixz="0.0" iyy="0.0010408333333333335" iyz="0.0" izz="0.0020000000000000005"/>
    </inertial>
  </link>
  <joint name="LF_wheel_joint" type="continuous">
    <parent link="chassis"/>
    <child link="LF_wheel"/>
    <origin rpy="0 1.57 -1.57" xyz="-0.333 0.333 0"/>
    <axis xyz="0 0 -1"/>
  </joint>
  <gazebo reference="LF_wheel">
    <material>Gazebo/Gray</material>
  </gazebo>
  <!-- Back Left wheel -->
  <link name="LB_wheel">
    <visual>
      <geometry>
        <cylinder length="0.07" radius="0.2"/>
      </geometry>
      <material name="gray"/>
    </visual>
    <collision>
      <geometry>
        <cylinder length="0.07" radius="0.2"/>
      </geometry>
    </collision>
    <inertial>
      <origin rpy="0 0 0" xyz="0 0 0"/>
      <mass value="0.1"/>
      <inertia ixx="0.0010408333333333335" ixy="0.0" ixz="0.0" iyy="0.0010408333333333335" iyz="0.0" izz="0.0020000000000000005"/>
    </inertial>
  </link>
  <joint name="LB_wheel_joint" type="continuous">
    <parent link="chassis"/>
    <child link="LB_wheel"/>
    <origin rpy="0 1.57 -1.57" xyz="-0.333 -0.333 0"/>
    <axis xyz="0 0 -1"/>
  </joint>
  <gazebo reference="LB_wheel">
    <material>Gazebo/Gray</material>
  </gazebo>
  <!-- Front Right Wheel -->
  <link name="RF_wheel">
    <visual>
      <geometry>
        <cylinder length="0.07" radius="0.2"/>
      </geometry>
      <material name="gray"/>
    </visual>
    <collision>
      <geometry>
        <cylinder length="0.07" radius="0.2"/>
      </geometry>
    </collision>
    <inertial>
      <origin rpy="0 0 0" xyz="0 0 0"/>
      <mass value="0.1"/>
      <inertia ixx="0.0010408333333333335" ixy="0.0" ixz="0.0" iyy="0.0010408333333333335" iyz="0.0" izz="0.0020000000000000005"/>
    </inertial>
  </link>
  <joint name="RF_wheel_joint" type="continuous">
    <parent link="chassis"/>
    <child link="RF_wheel"/>
    <origin rpy="0 1.57 -1.57" xyz="0.333 0.333 0"/>
    <axis xyz="0 0 -1"/>
  </joint>
  <gazebo reference="RF_wheel">
    <material>Gazebo/Gray</material>
  </gazebo>
  <!-- Back Right Wheel -->
  <link name="RB_wheel">
    <visual>
      <geometry>
        <cylinder length="0.07" radius="0.2"/>
      </geometry>
      <material name="gray"/>
    </visual>
    <collision>
      <geometry>
        <cylinder length="0.07" radius="0.2"/>
      </geometry>
    </collision>
    <inertial>
      <origin rpy="0 0 0" xyz="0 0 0"/>
      <mass value="0.1"/>
      <inertia ixx="0.0010408333333333335" ixy="0.0" ixz="0.0" iyy="0.0010408333333333335" iyz="0.0" izz="0.0020000000000000005"/>
    </inertial>
  </link>
  <joint name="RB_wheel_joint" type="continuous">
    <parent link="chassis"/>
    <child link="RB_wheel"/>
    <origin rpy="0 1.57 -1.57" xyz="0.333 -0.333 0"/>
    <axis xyz="0 0 -1"/>
  </joint>
  <gazebo reference="RB_wheel">
    <material>Gazebo/Gray</material>
  </gazebo>
  <!-- Lidar -->
  <link name="lidar">
    <visual>
      <geometry>
        <cylinder length="0.25" radius="0.15"/>
      </geometry>
      <origin rpy="0 0 0" xyz="-0.16 0 0.1"/>
      <material name="blue"/>
    </visual>
    <collision>
      <geometry>
        <cylinder length="0.25" radius="0.15"/>
      </geometry>
    </collision>
    <inertial>
      <origin rpy="0 0 0" xyz="-0.16 0 0.1"/>
      <mass value="0.2"/>
      <inertia ixx="0.0021666666666666666" ixy="0.0" ixz="0.0" iyy="0.0021666666666666666" iyz="0.0" izz="0.00225"/>
    </inertial>
  </link>
  <joint name="lidar_joint" type="fixed">
    <parent link="chassis"/>
    <child link="lidar"/>
    <origin rpy="0 0 0" xyz="0 0 0"/>
  </joint>
  <gazebo reference="lidar">
    <material>Gazebo/Indigo</material>
  </gazebo>
  <!-- Camera-->
  <link name="camera">
    <visual>
      <geometry>
        <box size="0.15 0.15 0.08"/>
      </geometry>
      <origin rpy="0 0 0" xyz="0.2 0 0.05"/>
      <material name="blue"/>
    </visual>
    <collision>
      <geometry>
        <box size="0.15 0.15 0.08"/>
      </geometry>
      <origin rpy="0 0 0" xyz="0.2 0 0.05"/>
    </collision>
    <inertial>
      <origin rpy="0 0 0" xyz="0 0 0"/>
      <mass value="0.2"/>
      <inertia ixx="0.00048166666666666665" ixy="0.0" ixz="0.0" iyy="0.00048166666666666665" iyz="0.0" izz="0.00075"/>
    </inertial>
  </link>
  <joint name="camera_joint" type="fixed">
    <parent link="chassis"/>
    <child link="camera"/>
    <origin rpy="0 0 0" xyz="0 0 0"/>
  </joint>
  <gazebo reference="camera">
    <material>Gazebo/Indigo</material>
  </gazebo>
  <!-- Hardware interface for the control manager-->
  <ros2_control name="GazeboSystem" type="system">
    <hardware>
      <plugin>gazebo_ros2_control/GazeboSystem</plugin>
    </hardware>
    <!-- Joints for four wheels-->
    <joint name="LF_wheel_joint">
      <command_interface name="velocity">
        <param name="min">-100</param>
        <param name="max">100</param>
      </command_interface>
      <state_interface name="velocity"/>
      <state_interface name="position"/>
    </joint>
    <joint name="RF_wheel_joint">
      <command_interface name="velocity">
        <param name="min">-100</param>
        <param name="max">100</param>
      </command_interface>
      <state_interface name="velocity"/>
      <state_interface name="position"/>
    </joint>
    <joint name="LB_wheel_joint">
      <command_interface name="velocity">
        <param name="min">-100</param>
        <param name="max">100</param>
      </command_interface>
      <state_interface name="velocity"/>
      <state_interface name="position"/>
    </joint>
    <joint name="RB_wheel_joint">
      <command_interface name="velocity">
        <param name="min">-100</param>
        <param name="max">100</param>
      </command_interface>
      <state_interface name="velocity"/>
      <state_interface name="position"/>
    </joint>
  </ros2_control>
  <!-- Gazebo Plugin, that tells gazebo to use ros2 control-->
  <gazebo>
    <plugin filename="libgazebo_ros2_control.so" name="gazebo_ros2_control">
      <parameters>/home/ali/workspacesROS/swarmRobots_ws/swarm_robots_ROS2/install/robot_description/share/robot_description/config/my_controllers.yaml</parameters>
    </plugin>
  </gazebo>
  <gazebo reference="lidar">
    <sensor name="lidar_sensor" type="ray">
      <pose>0 0 0 0 0 0</pose>
      <always_on>true</always_on>
      <visualize>true</visualize>
      <update_rate>5</update_rate>
      <ray>
        <scan>
          <horizontal>
            <samples>360</samples>
            <min_angle>0.0</min_angle>
            <max_angle>6.28</max_angle>
          </horizontal>
        </scan>
        <range>
          <min>1.0</min>
          <max>3.5</max>
        </range>
      </ray>
      <plugin filename="libgazebo_ros_ray_sensor.so" name="laser_controller">
        <ros>
          <!-- publish LaserScan message to the topic scan-->
          <argument>~/out:=scan</argument>
        </ros>
        <output_type>sensor_msgs/LaserScan</output_type>
        <frame_name>lidar</frame_name>
        <!-- lidar link name-->
      </plugin>
    </sensor>
  </gazebo>
  <gazebo reference="camera">
    <sensor name="camera1" type="camera">
      <update_rate>10.0</update_rate>
      <camera name="camera1">
        <pose>0 0.3 0 0 0 1.57</pose>
        <horizontal_fov>1.4</horizontal_fov>
        <image>
          <width>800</width>
          <height>800</height>
          <format>BGR8</format>
        </image>
        <clip>
          <near>0.02</near>
          <far>8.0</far>
        </clip>
      </camera>
      <plugin filename="libgazebo_ros_camera.so" name="camera_controller">
        <frameName>camera</frameName>
      </plugin>
    </sensor>
  </gazebo>
</robot>
