<?xml version="1.0" ?>
<!-- =================================================================================== -->
<!-- |    This document was autogenerated by xacro from BMW.urdf.xacro                 | -->
<!-- |    EDITING THIS FILE BY HAND IS NOT RECOMMENDED                                 | -->
<!-- =================================================================================== -->
<robot name="BMW_Car">
  <material name="blue">
    <color rgba="0 0.2 0.9 1"/>
  </material>
  <material name="gray">
    <color rgba="0.1 0.1 0.1 1"/>
  </material>
  <material name="darkBlue">
    <color rgba="0 0 0.1 1"/>
  </material>
  <link name="dummy_link"/>
  <!-- Chassis -->
  <link name="chassis">
    <visual>
      <geometry>
        <box size="0.6 0.7 0.1"/>
      </geometry>
      <origin rpy="0 0 0" xyz="0 0 0"/>
      <material name="darkBlue"/>
    </visual>
    <collision>
      <geometry>
        <box size="0.6 0.7 0.1"/>
      </geometry>
      <origin rpy="0 0 0" xyz="0 0 0"/>
    </collision>
    <inertial>
      <origin rpy="0 0 0" xyz="0 0 0"/>
      <mass value="0.5"/>
      <inertia ixx="0.02083333333333333" ixy="0.0" ixz="0.0" iyy="0.015416666666666665" iyz="0.0" izz="0.03541666666666666"/>
    </inertial>
  </link>
  <joint name="chassis_joint" type="fixed">
    <parent link="dummy_link"/>
    <child link="chassis"/>
    <origin xyz="0 0 0"/>
  </joint>
  <gazebo reference="chassis">
    <material>Gazebo/DarkMagentaTransparent</material>
  </gazebo>
  <!-- Front Left Wheel -->
  <link name="LF_wheel">
    <visual>
      <geometry>
        <cylinder length="0.07" radius="0.2"/>
      </geometry>
      <material name="gray"/>
    </visual>
    <collision>
      <geometry>
        <cylinder length="0.07" radius="0.2"/>
      </geometry>
    </collision>
    <inertial>
      <origin rpy="0 0 0" xyz="0 0 0"/>
      <mass value="0.1"/>
      <inertia ixx="0.0010408333333333335" ixy="0.0" ixz="0.0" iyy="0.0010408333333333335" iyz="0.0" izz="0.0020000000000000005"/>
    </inertial>
  </link>
  <joint name="LF_wheel_joint" type="continuous">
    <parent link="chassis"/>
    <child link="LF_wheel"/>
    <origin rpy="0 1.57 0" xyz="-0.333 0.3 0"/>
    <axis xyz="0 0 -1"/>
  </joint>
  <gazebo reference="LF_wheel">
    <material>Gazebo/Gray</material>
  </gazebo>
  <!-- Back Left wheel -->
  <link name="LB_wheel">
    <visual>
      <geometry>
        <cylinder length="0.07" radius="0.2"/>
      </geometry>
      <material name="gray"/>
    </visual>
    <collision>
      <geometry>
        <cylinder length="0.07" radius="0.2"/>
      </geometry>
    </collision>
    <inertial>
      <origin rpy="0 0 0" xyz="0 0 0"/>
      <mass value="0.1"/>
      <inertia ixx="0.0010408333333333335" ixy="0.0" ixz="0.0" iyy="0.0010408333333333335" iyz="0.0" izz="0.0020000000000000005"/>
    </inertial>
  </link>
  <joint name="LB_wheel_joint" type="continuous">
    <parent link="chassis"/>
    <child link="LB_wheel"/>
    <origin rpy="0 1.57 0" xyz="-0.333 -0.3 0"/>
    <axis xyz="0 0 -1"/>
  </joint>
  <gazebo reference="LB_wheel">
    <material>Gazebo/Gray</material>
  </gazebo>
  <!-- Front Right Wheel -->
  <link name="RF_wheel">
    <visual>
      <geometry>
        <cylinder length="0.07" radius="0.2"/>
      </geometry>
      <material name="gray"/>
    </visual>
    <collision>
      <geometry>
        <cylinder length="0.07" radius="0.2"/>
      </geometry>
    </collision>
    <inertial>
      <origin rpy="0 0 0" xyz="0 0 0"/>
      <mass value="0.1"/>
      <inertia ixx="0.0010408333333333335" ixy="0.0" ixz="0.0" iyy="0.0010408333333333335" iyz="0.0" izz="0.0020000000000000005"/>
    </inertial>
  </link>
  <joint name="RF_wheel_joint" type="continuous">
    <parent link="chassis"/>
    <child link="RF_wheel"/>
    <origin rpy="0 1.57 0" xyz="0.333 0.3 0"/>
    <axis xyz="0 0 1"/>
  </joint>
  <gazebo reference="RF_wheel">
    <material>Gazebo/Gray</material>
  </gazebo>
  <!-- Back Right Wheel -->
  <link name="RB_wheel">
    <visual>
      <geometry>
        <cylinder length="0.07" radius="0.2"/>
      </geometry>
      <material name="gray"/>
    </visual>
    <collision>
      <geometry>
        <cylinder length="0.07" radius="0.2"/>
      </geometry>
    </collision>
    <inertial>
      <origin rpy="0 0 0" xyz="0 0 0"/>
      <mass value="0.1"/>
      <inertia ixx="0.0010408333333333335" ixy="0.0" ixz="0.0" iyy="0.0010408333333333335" iyz="0.0" izz="0.0020000000000000005"/>
    </inertial>
  </link>
  <joint name="RB_wheel_joint" type="continuous">
    <parent link="chassis"/>
    <child link="RB_wheel"/>
    <origin rpy="0 1.57 0" xyz="0.333 -0.3 0"/>
    <axis xyz="0 0 1"/>
  </joint>
  <gazebo reference="RB_wheel">
    <material>Gazebo/Gray</material>
  </gazebo>
  <!-- Lidar -->
  <link name="lidar">
    <visual>
      <geometry>
        <cylinder length="0.25" radius="0.15"/>
      </geometry>
      <origin rpy="0 0 0" xyz="0 -0.16 0.1"/>
      <material name="blue"/>
    </visual>
    <collision>
      <geometry>
        <cylinder length="0.25" radius="0.15"/>
      </geometry>
    </collision>
    <inertial>
      <origin rpy="0 0 0" xyz="0 0 0"/>
      <mass value="0.2"/>
      <inertia ixx="0.0021666666666666666" ixy="0.0" ixz="0.0" iyy="0.0021666666666666666" iyz="0.0" izz="0.00225"/>
    </inertial>
  </link>
  <joint name="lidar_joint" type="fixed">
    <parent link="chassis"/>
    <child link="lidar"/>
    <origin rpy="0 0 0" xyz="0 0 0"/>
  </joint>
  <gazebo reference="lidar">
    <material>Gazebo/Indigo</material>
  </gazebo>
  <!-- Camera-->
  <link name="camera">
    <visual>
      <geometry>
        <box size="0.15 0.15 0.08"/>
      </geometry>
      <origin rpy="0 0 0" xyz="0 0.2 0.05"/>
      <material name="blue"/>
    </visual>
    <collision>
      <geometry>
        <box size="0.15 0.15 0.08"/>
      </geometry>
      <origin rpy="0 0 0" xyz="0 0.2 0.05"/>
    </collision>
    <inertial>
      <origin rpy="0 0 0" xyz="0 0 0"/>
      <mass value="0.2"/>
      <inertia ixx="0.00048166666666666665" ixy="0.0" ixz="0.0" iyy="0.00048166666666666665" iyz="0.0" izz="0.00075"/>
    </inertial>
  </link>
  <joint name="camera_joint" type="fixed">
    <parent link="chassis"/>
    <child link="camera"/>
    <origin rpy="0 0 0" xyz="0 0 0"/>
  </joint>
  <gazebo reference="camera">
    <material>Gazebo/Indigo</material>
  </gazebo>
</robot>
